Workbook

Sheet Dashboard
A1: IDX VALUE SCREENER — DASHBOARD
A2: Every figure below is a live formula against the RAW_* sheets. Rebuild the workbook to refresh the membership of the ranked tables.
A4: DATA & UNIVERSE
A5: Last data refresh (Fetched At) | D5: =RAW_key_statistics!$EF$2
A6: Tickers in universe | D6: =COUNTA(Screener!$A$2:$A$957)
A7: Names at/above MOS Buy threshold | D7: =COUNTIF(Screener!$AC$2:$AC$957,">="&Setup!$B$9)
A8: Names at/above MOS Watch threshold | D8: =COUNTIF(Screener!$AC$2:$AC$957,">="&Setup!$B$10)
A10: VERDICT SPLIT | F10: MARKET CONTEXT (universe medians)
A11: Verdict | B11: Count | C11: % of universe | F11: Measure | G11: Value
A12: BUY | B12: =COUNTIF(Screener!$AI$2:$AI$957,"BUY") | C12: =IFERROR(B12/$D$6,"") | F12: Median PE (TTM) | G12: =IFERROR(MEDIAN(Screener!$G$2:$G$957),"")
A13: DEEP VALUE | B13: =COUNTIF(Screener!$AI$2:$AI$957,"DEEP VALUE") | C13: =IFERROR(B13/$D$6,"") | F13: Median PB | G13: =IFERROR(MEDIAN(Screener!$H$2:$H$957),"")
A14: WATCH | B14: =COUNTIF(Screener!$AI$2:$AI$957,"WATCH") | C14: =IFERROR(B14/$D$6,"") | F14: Median EV/EBIT | G14: =IFERROR(MEDIAN(Screener!$I$2:$I$957),"")
A15: SKIP | B15: =COUNTIF(Screener!$AI$2:$AI$957,"SKIP") | C15: =IFERROR(B15/$D$6,"") | F15: Names with F-Score >= 7 | G15: =COUNTIF(Screener!$Q$2:$Q$957,">=7")
F16: Names with Altman Z < 1.1 | G16: =COUNTIF(Screener!$R$2:$R$957,"<1.1")
F17: Median MOS (blended) | G17: =IFERROR(MEDIAN(Screener!$AC$2:$AC$957),"")
A20: TOP IDEAS — highest Composite Score among BUY / DEEP VALUE
A21: Membership fixed at build time (SORT/FILTER are not portable); all displayed figures are live INDEX/MATCH lookups.
A22: Rank | B22: Ticker | C22: Name | D22: Sector | E22: Business Type | F22: Price | G22: Blended IV | H22: MOS | I22: Composite | J22: Quality | K22: Safety | L22: Value | M22: F-Score | N22: Verdict
A23: 1 | B23: CASS | C23: =IFERROR(IF(ISBLANK(INDEX(Screener!$B$2:$B$957,MATCH($B23,Screener!$A$2:$A$957,0))),"",INDEX(Screener!$B$2:$B$957,MATCH($B23,Screener!$A$2:$A$957,0))),"") | D23: =IFERROR(IF(ISBLANK(INDEX(Screener!$C$2:$C$957,MATCH($B23,Screener!$A$2:$A$957,0))),"",INDEX(Screener!$C$2:$C$957,MATCH($B23,Screener!$A$2:$A$957,0))),"") | E23: =IFERROR(IF(ISBLANK(INDEX(Screener!$D$2:$D$957,MATCH($B23,Screener!$A$2:$A$957,0))),"",INDEX(Screener!$D$2:$D$957,MATCH($B23,Screener!$A$2:$A$957,0))),"") | F23: =IFERROR(IF(ISBLANK(INDEX(Screener!$E$2:$E$957,MATCH($B23,Screener!$A$2:$A$957,0))),"",INDEX(Screener!$E$2:$E$957,MATCH($B23,Screener!$A$2:$A$957,0))),"") | G23: =IFERROR(IF(ISBLANK(INDEX(Screener!$AB$2:$AB$957,MATCH($B23,Screener!$A$2:$A$957,0))),"",INDEX(Screener!$AB$2:$AB$957,MATCH($B23,Screener!$A$2:$A$957,0))),"") | H23: =IFERROR(IF(ISBLANK(INDEX(Screener!$AC$2:$AC$957,MATCH($B23,Screener!$A$2:$A$957,0))),"",INDEX(Screener!$AC$2:$AC$957,MATCH($B23,Screener!$A$2:$A$957,0))),"") | I23: =IFERROR(IF(ISBLANK(INDEX(Screener!$AH$2:$AH$957,MATCH($B23,Screener!$A$2:$A$957,0))),"",INDEX(Screener!$AH$2:$AH$957,MATCH($B23,Screener!$A$2:$A$957,0))),"") | J23: =IFERROR(IF(ISBLANK(INDEX(Screener!$AE$2:$AE$957,MATCH($B23,Screener!$A$2:$A$957,0))),"",INDEX(Screener!$AE$2:$AE$957,MATCH($B23,Screener!$A$2:$A$957,0))),"") | K23: =IFERROR(IF(ISBLANK(INDEX(Screener!$AF$2:$AF$957,MATCH($B23,Screener!$A$2:$A$957,0))),"",INDEX(Screener!$AF$2:$AF$957,MATCH($B23,Screener!$A$2:$A$957,0))),"") | L23: =IFERROR(IF(ISBLANK(INDEX(Screener!$AG$2:$AG$957,MATCH($B23,Screener!$A$2:$A$957,0))),"",INDEX(Screener!$AG$2:$AG$957,MATCH($B23,Screener!$A$2:$A$957,0))),"") | M23: =IFERROR(IF(ISBLANK(INDEX(Screener!$Q$2:$Q$957,MATCH($B23,Screener!$A$2:$A$957,0))),"",INDEX(Screener!$Q$2:$Q$957,MATCH($B23,Screener!$A$2:$A$957,0))),"") | N23: =IFERROR(IF(ISBLANK(INDEX(Screener!$AI$2:$AI$957,MATCH($B23,Screener!$A$2:$A$957,0))),"",INDEX(Screener!$AI$2:$AI$957,MATCH($B23,Screener!$A$2:$A$957,0))),"")
A24: 2 | B24: DMAS | C24: =IFERROR(IF(ISBLANK(INDEX(Screener!$B$2:$B$957,MATCH($B24,Screener!$A$2:$A$957,0))),"",INDEX(Screener!$B$2:$B$957,MATCH($B24,Screener!$A$2:$A$957,0))),"") | D24: =IFERROR(IF(ISBLANK(INDEX(Screener!$C$2:$C$957,MATCH($B24,Screener!$A$2:$A$957,0))),"",INDEX(Screener!$C$2:$C$957,MATCH($B24,Screener!$A$2:$A$957,0))),"") | E24: =IFERROR(IF(ISBLANK(INDEX(Screener!$D$2:$D$957,MATCH($B24,Screener!$A$2:$A$957,0))),"",INDEX(Screener!$D$2:$D$957,MATCH($B24,Screener!$A$2:$A$957,0))),"") | F24: =IFERROR(IF(ISBLANK(INDEX(Screener!$E$2:$E$957,MATCH($B24,Screener!$A$2:$A$957,0))),"",INDEX(Screener!$E$2:$E$957,MATCH($B24,Screener!$A$2:$A$957,0))),"") | G24: =IFERROR(IF(ISBLANK(INDEX(Screener!$AB$2:$AB$957,MATCH($B24,Screener!$A$2:$A$957,0))),"",INDEX(Screener!$AB$2:$AB$957,MATCH($B24,Screener!$A$2:$A$957,0))),"") | H24: =IFERROR(IF(ISBLANK(INDEX(Screener!$AC$2:$AC$957,MATCH($B24,Screener!$A$2:$A$957,0))),"",INDEX(Screener!$AC$2:$AC$957,MATCH($B24,Screener!$A$2:$A$957,0))),"") | I24: =IFERROR(IF(ISBLANK(INDEX(Screener!$AH$2:$AH$957,MATCH($B24,Screener!$A$2:$A$957,0))),"",INDEX(Screener!$AH$2:$AH$957,MATCH($B24,Screener!$A$2:$A$957,0))),"") | J24: =IFERROR(IF(ISBLANK(INDEX(Screener!$AE$2:$AE$957,MATCH($B24,Screener!$A$2:$A$957,0))),"",INDEX(Screener!$AE$2:$AE$957,MATCH($B24,Screener!$A$2:$A$957,0))),"") | K24: =IFERROR(IF(ISBLANK(INDEX(Screener!$AF$2:$AF$957,MATCH($B24,Screener!$A$2:$A$957,0))),"",INDEX(Screener!$AF$2:$AF$957,MATCH($B24,Screener!$A$2:$A$957,0))),"") | L24: =IFERROR(IF(ISBLANK(INDEX(Screener!$AG$2:$AG$957,MATCH($B24,Screener!$A$2:$A$957,0))),"",INDEX(Screener!$AG$2:$AG$957,MATCH($B24,Screener!$A$2:$A$957,0))),"") | M24: =IFERROR(IF(ISBLANK(INDEX(Screener!$Q$2:$Q$957,MATCH($B24,Screener!$A$2:$A$957,0))),"",INDEX(Screener!$Q$2:$Q$957,MATCH($B24,Screener!$A$2:$A$957,0))),"") | N24: =IFERROR(IF(ISBLANK(INDEX(Screener!$AI$2:$AI$957,MATCH($B24,Screener!$A$2:$A$957,0))),"",INDEX(Screener!$AI$2:$AI$957,MATCH($B24,Screener!$A$2:$A$957,0))),"")
A25: 3 | B25: MAPI | C25: =IFERROR(IF(ISBLANK(INDEX(Screener!$B$2:$B$957,MATCH($B25,Screener!$A$2:$A$957,0))),"",INDEX(Screener!$B$2:$B$957,MATCH($B25,Screener!$A$2:$A$957,0))),"") | D25: =IFERROR(IF(ISBLANK(INDEX(Screener!$C$2:$C$957,MATCH($B25,Screener!$A$2:$A$957,0))),"",INDEX(Screener!$C$2:$C$957,MATCH($B25,Screener!$A$2:$A$957,0))),"") | E25: =IFERROR(IF(ISBLANK(INDEX(Screener!$D$2:$D$957,MATCH($B25,Screener!$A$2:$A$957,0))),"",INDEX(Screener!$D$2:$D$957,MATCH($B25,Screener!$A$2:$A$957,0))),"") | F25: =IFERROR(IF(ISBLANK(INDEX(Screener!$E$2:$E$957,MATCH($B25,Screener!$A$2:$A$957,0))),"",INDEX(Screener!$E$2:$E$957,MATCH($B25,Screener!$A$2:$A$957,0))),"") | G25: =IFERROR(IF(ISBLANK(INDEX(Screener!$AB$2:$AB$957,MATCH($B25,Screener!$A$2:$A$957,0))),"",INDEX(Screener!$AB$2:$AB$957,MATCH($B25,Screener!$A$2:$A$957,0))),"") | H25: =IFERROR(IF(ISBLANK(INDEX(Screener!$AC$2:$AC$957,MATCH($B25,Screener!$A$2:$A$957,0))),"",INDEX(Screener!$AC$2:$AC$957,MATCH($B25,Screener!$A$2:$A$957,0))),"") | I25: =IFERROR(IF(ISBLANK(INDEX(Screener!$AH$2:$AH$957,MATCH($B25,Screener!$A$2:$A$957,0))),"",INDEX(Screener!$AH$2:$AH$957,MATCH($B25,Screener!$A$2:$A$957,0))),"") | J25: =IFERROR(IF(ISBLANK(INDEX(Screener!$AE$2:$AE$957,MATCH($B25,Screener!$A$2:$A$957,0))),"",INDEX(Screener!$AE$2:$AE$957,MATCH($B25,Screener!$A$2:$A$957,0))),"") | K25: =IFERROR(IF(ISBLANK(INDEX(Screener!$AF$2:$AF$957,MATCH($B25,Screener!$A$2:$A$957,0))),"",INDEX(Screener!$AF$2:$AF$957,MATCH($B25,Screener!$A$2:$A$957,0))),"") | L25: =IFERROR(IF(ISBLANK(INDEX(Screener!$AG$2:$AG$957,MATCH($B25,Screener!$A$2:$A$957,0))),"",INDEX(Screener!$AG$2:$AG$957,MATCH($B25,Screener!$A$2:$A$957,0))),"") | M25: =IFERROR(IF(ISBLANK(INDEX(Screener!$Q$2:$Q$957,MATCH($B25,Screener!$A$2:$A$957,0))),"",INDEX(Screener!$Q$2:$Q$957,MATCH($B25,Screener!$A$2:$A$957,0))),"") | N25: =IFERROR(IF(ISBLANK(INDEX(Screener!$AI$2:$AI$957,MATCH($B25,Screener!$A$2:$A$957,0))),"",INDEX(Screener!$AI$2:$AI$957,MATCH($B25,Screener!$A$2:$A$957,0))),"")
A26: 4 | B26: LSIP | C26: =IFERROR(IF(ISBLANK(INDEX(Screener!$B$2:$B$957,MATCH($B26,Screener!$A$2:$A$957,0))),"",INDEX(Screener!$B$2:$B$957,MATCH($B26,Screener!$A$2:$A$957,0))),"") | D26: =IFERROR(IF(ISBLANK(INDEX(Screener!$C$2:$C$957,MATCH($B26,Screener!$A$2:$A$957,0))),"",INDEX(Screener!$C$2:$C$957,MATCH($B26,Screener!$A$2:$A$957,0))),"") | E26: =IFERROR(IF(ISBLANK(INDEX(Screener!$D$2:$D$957,MATCH($B26,Screener!$A$2:$A$957,0))),"",INDEX(Screener!$D$2:$D$957,MATCH($B26,Screener!$A$2:$A$957,0))),"") | F26: =IFERROR(IF(ISBLANK(INDEX(Screener!$E$2:$E$957,MATCH($B26,Screener!$A$2:$A$957,0))),"",INDEX(Screener!$E$2:$E$957,MATCH($B26,Screener!$A$2:$A$957,0))),"") | G26: =IFERROR(IF(ISBLANK(INDEX(Screener!$AB$2:$AB$957,MATCH($B26,Screener!$A$2:$A$957,0))),"",INDEX(Screener!$AB$2:$AB$957,MATCH($B26,Screener!$A$2:$A$957,0))),"") | H26: =IFERROR(IF(ISBLANK(INDEX(Screener!$AC$2:$AC$957,MATCH($B26,Screener!$A$2:$A$957,0))),"",INDEX(Screener!$AC$2:$AC$957,MATCH($B26,Screener!$A$2:$A$957,0))),"") | I26: =IFERROR(IF(ISBLANK(INDEX(Screener!$AH$2:$AH$957,MATCH($B26,Screener!$A$2:$A$957,0))),"",INDEX(Screener!$AH$2:$AH$957,MATCH($B26,Screener!$A$2:$A$957,0))),"") | J26: =IFERROR(IF(ISBLANK(INDEX(Screener!$AE$2:$AE$957,MATCH($B26,Screener!$A$2:$A$957,0))),"",INDEX(Screener!$AE$2:$AE$957,MATCH($B26,Screener!$A$2:$A$957,0))),"") | K26: =IFERROR(IF(ISBLANK(INDEX(Screener!$AF$2:$AF$957,MATCH($B26,Screener!$A$2:$A$957,0))),"",INDEX(Screener!$AF$2:$AF$957,MATCH($B26,Screener!$A$2:$A$957,0))),"") | L26: =IFERROR(IF(ISBLANK(INDEX(Screener!$AG$2:$AG$957,MATCH($B26,Screener!$A$2:$A$957,0))),"",INDEX(Screener!$AG$2:$AG$957,MATCH($B26,Screener!$A$2:$A$957,0))),"") | M26: =IFERROR(IF(ISBLANK(INDEX(Screener!$Q$2:$Q$957,MATCH($B26,Screener!$A$2:$A$957,0))),"",INDEX(Screener!$Q$2:$Q$957,MATCH($B26,Screener!$A$2:$A$957,0))),"") | N26: =IFERROR(IF(ISBLANK(INDEX(Screener!$AI$2:$AI$957,MATCH($B26,Screener!$A$2:$A$957,0))),"",INDEX(Screener!$AI$2:$AI$957,MATCH($B26,Screener!$A$2:$A$957,0))),"")
A27: 5 | B27: CTRA | C27: =IFERROR(IF(ISBLANK(INDEX(Screener!$B$2:$B$957,MATCH($B27,Screener!$A$2:$A$957,0))),"",INDEX(Screener!$B$2:$B$957,MATCH($B27,Screener!$A$2:$A$957,0))),"") | D27: =IFERROR(IF(ISBLANK(INDEX(Screener!$C$2:$C$957,MATCH($B27,Screener!$A$2:$A$957,0))),"",INDEX(Screener!$C$2:$C$957,MATCH($B27,Screener!$A$2:$A$957,0))),"") | E27: =IFERROR(IF(ISBLANK(INDEX(Screener!$D$2:$D$957,MATCH($B27,Screener!$A$2:$A$957,0))),"",INDEX(Screener!$D$2:$D$957,MATCH($B27,Screener!$A$2:$A$957,0))),"") | F27: =IFERROR(IF(ISBLANK(INDEX(Screener!$E$2:$E$957,MATCH($B27,Screener!$A$2:$A$957,0))),"",INDEX(Screener!$E$2:$E$957,MATCH($B27,Screener!$A$2:$A$957,0))),"") | G27: =IFERROR(IF(ISBLANK(INDEX(Screener!$AB$2:$AB$957,MATCH($B27,Screener!$A$2:$A$957,0))),"",INDEX(Screener!$AB$2:$AB$957,MATCH($B27,Screener!$A$2:$A$957,0))),"") | H27: =IFERROR(IF(ISBLANK(INDEX(Screener!$AC$2:$AC$957,MATCH($B27,Screener!$A$2:$A$957,0))),"",INDEX(Screener!$AC$2:$AC$957,MATCH($B27,Screener!$A$2:$A$957,0))),"") | I27: =IFERROR(IF(ISBLANK(INDEX(Screener!$AH$2:$AH$957,MATCH($B27,Screener!$A$2:$A$957,0))),"",INDEX(Screener!$AH$2:$AH$957,MATCH($B27,Screener!$A$2:$A$957,0))),"") | J27: =IFERROR(IF(ISBLANK(INDEX(Screener!$AE$2:$AE$957,MATCH($B27,Screener!$A$2:$A$957,0))),"",INDEX(Screener!$AE$2:$AE$957,MATCH($B27,Screener!$A$2:$A$957,0))),"") | K27: =IFERROR(IF(ISBLANK(INDEX(Screener!$AF$2:$AF$957,MATCH($B27,Screener!$A$2:$A$957,0))),"",INDEX(Screener!$AF$2:$AF$957,MATCH($B27,Screener!$A$2:$A$957,0))),"") | L27: =IFERROR(IF(ISBLANK(INDEX(Screener!$AG$2:$AG$957,MATCH($B27,Screener!$A$2:$A$957,0))),"",INDEX(Screener!$AG$2:$AG$957,MATCH($B27,Screener!$A$2:$A$957,0))),"") | M27: =IFERROR(IF(ISBLANK(INDEX(Screener!$Q$2:$Q$957,MATCH($B27,Screener!$A$2:$A$957,0))),"",INDEX(Screener!$Q$2:$Q$957,MATCH($B27,Screener!$A$2:$A$957,0))),"") | N27: =IFERROR(IF(ISBLANK(INDEX(Screener!$AI$2:$AI$957,MATCH($B27,Screener!$A$2:$A$957,0))),"",INDEX(Screener!$AI$2:$AI$957,MATCH($B27,Screener!$A$2:$A$957,0))),"")
A28: 6 | B28: PWON | C28: =IFERROR(IF(ISBLANK(INDEX(Screener!$B$2:$B$957,MATCH($B28,Screener!$A$2:$A$957,0))),"",INDEX(Screener!$B$2:$B$957,MATCH($B28,Screener!$A$2:$A$957,0))),"") | D28: =IFERROR(IF(ISBLANK(INDEX(Screener!$C$2:$C$957,MATCH($B28,Screener!$A$2:$A$957,0))),"",INDEX(Screener!$C$2:$C$957,MATCH($B28,Screener!$A$2:$A$957,0))),"") | E28: =IFERROR(IF(ISBLANK(INDEX(Screener!$D$2:$D$957,MATCH($B28,Screener!$A$2:$A$957,0))),"",INDEX(Screener!$D$2:$D$957,MATCH($B28,Screener!$A$2:$A$957,0))),"") | F28: =IFERROR(IF(ISBLANK(INDEX(Screener!$E$2:$E$957,MATCH($B28,Screener!$A$2:$A$957,0))),"",INDEX(Screener!$E$2:$E$957,MATCH($B28,Screener!$A$2:$A$957,0))),"") | G28: =IFERROR(IF(ISBLANK(INDEX(Screener!$AB$2:$AB$957,MATCH($B28,Screener!$A$2:$A$957,0))),"",INDEX(Screener!$AB$2:$AB$957,MATCH($B28,Screener!$A$2:$A$957,0))),"") | H28: =IFERROR(IF(ISBLANK(INDEX(Screener!$AC$2:$AC$957,MATCH($B28,Screener!$A$2:$A$957,0))),"",INDEX(Screener!$AC$2:$AC$957,MATCH($B28,Screener!$A$2:$A$957,0))),"") | I28: =IFERROR(IF(ISBLANK(INDEX(Screener!$AH$2:$AH$957,MATCH($B28,Screener!$A$2:$A$957,0))),"",INDEX(Screener!$AH$2:$AH$957,MATCH($B28,Screener!$A$2:$A$957,0))),"") | J28: =IFERROR(IF(ISBLANK(INDEX(Screener!$AE$2:$AE$957,MATCH($B28,Screener!$A$2:$A$957,0))),"",INDEX(Screener!$AE$2:$AE$957,MATCH($B28,Screener!$A$2:$A$957,0))),"") | K28: =IFERROR(IF(ISBLANK(INDEX(Screener!$AF$2:$AF$957,MATCH($B28,Screener!$A$2:$A$957,0))),"",INDEX(Screener!$AF$2:$AF$957,MATCH($B28,Screener!$A$2:$A$957,0))),"") | L28: =IFERROR(IF(ISBLANK(INDEX(Screener!$AG$2:$AG$957,MATCH($B28,Screener!$A$2:$A$957,0))),"",INDEX(Screener!$AG$2:$AG$957,MATCH($B28,Screener!$A$2:$A$957,0))),"") | M28: =IFERROR(IF(ISBLANK(INDEX(Screener!$Q$2:$Q$957,MATCH($B28,Screener!$A$2:$A$957,0))),"",INDEX(Screener!$Q$2:$Q$957,MATCH($B28,Screener!$A$2:$A$957,0))),"") | N28: =IFERROR(IF(ISBLANK(INDEX(Screener!$AI$2:$AI$957,MATCH($B28,Screener!$A$2:$A$957,0))),"",INDEX(Screener!$AI$2:$AI$957,MATCH($B28,Screener!$A$2:$A$957,0))),"")
A29: 7 | B29: MSTI | C29: =IFERROR(IF(ISBLANK(INDEX(Screener!$B$2:$B$957,MATCH($B29,Screener!$A$2:$A$957,0))),"",INDEX(Screener!$B$2:$B$957,MATCH($B29,Screener!$A$2:$A$957,0))),"") | D29: =IFERROR(IF(ISBLANK(INDEX(Screener!$C$2:$C$957,MATCH($B29,Screener!$A$2:$A$957,0))),"",INDEX(Screener!$C$2:$C$957,MATCH($B29,Screener!$A$2:$A$957,0))),"") | E29: =IFERROR(IF(ISBLANK(INDEX(Screener!$D$2:$D$957,MATCH($B29,Screener!$A$2:$A$957,0))),"",INDEX(Screener!$D$2:$D$957,MATCH($B29,Screener!$A$2:$A$957,0))),"") | F29: =IFERROR(IF(ISBLANK(INDEX(Screener!$E$2:$E$957,MATCH($B29,Screener!$A$2:$A$957,0))),"",INDEX(Screener!$E$2:$E$957,MATCH($B29,Screener!$A$2:$A$957,0))),"") | G29: =IFERROR(IF(ISBLANK(INDEX(Screener!$AB$2:$AB$957,MATCH($B29,Screener!$A$2:$A$957,0))),"",INDEX(Screener!$AB$2:$AB$957,MATCH($B29,Screener!$A$2:$A$957,0))),"") | H29: =IFERROR(IF(ISBLANK(INDEX(Screener!$AC$2:$AC$957,MATCH($B29,Screener!$A$2:$A$957,0))),"",INDEX(Screener!$AC$2:$AC$957,MATCH($B29,Screener!$A$2:$A$957,0))),"") | I29: =IFERROR(IF(ISBLANK(INDEX(Screener!$AH$2:$AH$957,MATCH($B29,Screener!$A$2:$A$957,0))),"",INDEX(Screener!$AH$2:$AH$957,MATCH($B29,Screener!$A$2:$A$957,0))),"") | J29: =IFERROR(IF(ISBLANK(INDEX(Screener!$AE$2:$AE$957,MATCH($B29,Screener!$A$2:$A$957,0))),"",INDEX(Screener!$AE$2:$AE$957,MATCH($B29,Screener!$A$2:$A$957,0))),"") | K29: =IFERROR(IF(ISBLANK(INDEX(Screener!$AF$2:$AF$957,MATCH($B29,Screener!$A$2:$A$957,0))),"",INDEX(Screener!$AF$2:$AF$957,MATCH($B29,Screener!$A$2:$A$957,0))),"") | L29: =IFERROR(IF(ISBLANK(INDEX(Screener!$AG$2:$AG$957,MATCH($B29,Screener!$A$2:$A$957,0))),"",INDEX(Screener!$AG$2:$AG$957,MATCH($B29,Screener!$A$2:$A$957,0))),"") | M29: =IFERROR(IF(ISBLANK(INDEX(Screener!$Q$2:$Q$957,MATCH($B29,Screener!$A$2:$A$957,0))),"",INDEX(Screener!$Q$2:$Q$957,MATCH($B29,Screener!$A$2:$A$957,0))),"") | N29: =IFERROR(IF(ISBLANK(INDEX(Screener!$AI$2:$AI$957,MATCH($B29,Screener!$A$2:$A$957,0))),"",INDEX(Screener!$AI$2:$AI$957,MATCH($B29,Screener!$A$2:$A$957,0))),"")
A30: 8 | B30: KIJA | C30: =IFERROR(IF(ISBLANK(INDEX(Screener!$B$2:$B$957,MATCH($B30,Screener!$A$2:$A$957,0))),"",INDEX(Screener!$B$2:$B$957,MATCH($B30,Screener!$A$2:$A$957,0))),"") | D30: =IFERROR(IF(ISBLANK(INDEX(Screener!$C$2:$C$957,MATCH($B30,Screener!$A$2:$A$957,0))),"",INDEX(Screener!$C$2:$C$957,MATCH($B30,Screener!$A$2:$A$957,0))),"") | E30: =IFERROR(IF(ISBLANK(INDEX(Screener!$D$2:$D$957,MATCH($B30,Screener!$A$2:$A$957,0))),"",INDEX(Screener!$D$2:$D$957,MATCH($B30,Screener!$A$2:$A$957,0))),"") | F30: =IFERROR(IF(ISBLANK(INDEX(Screener!$E$2:$E$957,MATCH($B30,Screener!$A$2:$A$957,0))),"",INDEX(Screener!$E$2:$E$957,MATCH($B30,Screener!$A$2:$A$957,0))),"") | G30: =IFERROR(IF(ISBLANK(INDEX(Screener!$AB$2:$AB$957,MATCH($B30,Screener!$A$2:$A$957,0))),"",INDEX(Screener!$AB$2:$AB$957,MATCH($B30,Screener!$A$2:$A$957,0))),"") | H30: =IFERROR(IF(ISBLANK(INDEX(Screener!$AC$2:$AC$957,MATCH($B30,Screener!$A$2:$A$957,0))),"",INDEX(Screener!$AC$2:$AC$957,MATCH($B30,Screener!$A$2:$A$957,0))),"") | I30: =IFERROR(IF(ISBLANK(INDEX(Screener!$AH$2:$AH$957,MATCH($B30,Screener!$A$2:$A$957,0))),"",INDEX(Screener!$AH$2:$AH$957,MATCH($B30,Screener!$A$2:$A$957,0))),"") | J30: =IFERROR(IF(ISBLANK(INDEX(Screener!$AE$2:$AE$957,MATCH($B30,Screener!$A$2:$A$957,0))),"",INDEX(Screener!$AE$2:$AE$957,MATCH($B30,Screener!$A$2:$A$957,0))),"") | K30: =IFERROR(IF(ISBLANK(INDEX(Screener!$AF$2:$AF$957,MATCH($B30,Screener!$A$2:$A$957,0))),"",INDEX(Screener!$AF$2:$AF$957,MATCH($B30,Screener!$A$2:$A$957,0))),"") | L30: =IFERROR(IF(ISBLANK(INDEX(Screener!$AG$2:$AG$957,MATCH($B30,Screener!$A$2:$A$957,0))),"",INDEX(Screener!$AG$2:$AG$957,MATCH($B30,Screener!$A$2:$A$957,0))),"") | M30: =IFERROR(IF(ISBLANK(INDEX(Screener!$Q$2:$Q$957,MATCH($B30,Screener!$A$2:$A$957,0))),"",INDEX(Screener!$Q$2:$Q$957,MATCH($B30,Screener!$A$2:$A$957,0))),"") | N30: =IFERROR(IF(ISBLANK(INDEX(Screener!$AI$2:$AI$957,MATCH($B30,Screener!$A$2:$A$957,0))),"",INDEX(Screener!$AI$2:$AI$957,MATCH($B30,Screener!$A$2:$A$957,0))),"")
A31: 9 | B31: MINE | C31: =IFERROR(IF(ISBLANK(INDEX(Screener!$B$2:$B$957,MATCH($B31,Screener!$A$2:$A$957,0))),"",INDEX(Screener!$B$2:$B$957,MATCH($B31,Screener!$A$2:$A$957,0))),"") | D31: =IFERROR(IF(ISBLANK(INDEX(Screener!$C$2:$C$957,MATCH($B31,Screener!$A$2:$A$957,0))),"",INDEX(Screener!$C$2:$C$957,MATCH($B31,Screener!$A$2:$A$957,0))),"") | E31: =IFERROR(IF(ISBLANK(INDEX(Screener!$D$2:$D$957,MATCH($B31,Screener!$A$2:$A$957,0))),"",INDEX(Screener!$D$2:$D$957,MATCH($B31,Screener!$A$2:$A$957,0))),"") | F31: =IFERROR(IF(ISBLANK(INDEX(Screener!$E$2:$E$957,MATCH($B31,Screener!$A$2:$A$957,0))),"",INDEX(Screener!$E$2:$E$957,MATCH($B31,Screener!$A$2:$A$957,0))),"") | G31: =IFERROR(IF(ISBLANK(INDEX(Screener!$AB$2:$AB$957,MATCH($B31,Screener!$A$2:$A$957,0))),"",INDEX(Screener!$AB$2:$AB$957,MATCH($B31,Screener!$A$2:$A$957,0))),"") | H31: =IFERROR(IF(ISBLANK(INDEX(Screener!$AC$2:$AC$957,MATCH($B31,Screener!$A$2:$A$957,0))),"",INDEX(Screener!$AC$2:$AC$957,MATCH($B31,Screener!$A$2:$A$957,0))),"") | I31: =IFERROR(IF(ISBLANK(INDEX(Screener!$AH$2:$AH$957,MATCH($B31,Screener!$A$2:$A$957,0))),"",INDEX(Screener!$AH$2:$AH$957,MATCH($B31,Screener!$A$2:$A$957,0))),"") | J31: =IFERROR(IF(ISBLANK(INDEX(Screener!$AE$2:$AE$957,MATCH($B31,Screener!$A$2:$A$957,0))),"",INDEX(Screener!$AE$2:$AE$957,MATCH($B31,Screener!$A$2:$A$957,0))),"") | K31: =IFERROR(IF(ISBLANK(INDEX(Screener!$AF$2:$AF$957,MATCH($B31,Screener!$A$2:$A$957,0))),"",INDEX(Screener!$AF$2:$AF$957,MATCH($B31,Screener!$A$2:$A$957,0))),"") | L31: =IFERROR(IF(ISBLANK(INDEX(Screener!$AG$2:$AG$957,MATCH($B31,Screener!$A$2:$A$957,0))),"",INDEX(Screener!$AG$2:$AG$957,MATCH($B31,Screener!$A$2:$A$957,0))),"") | M31: =IFERROR(IF(ISBLANK(INDEX(Screener!$Q$2:$Q$957,MATCH($B31,Screener!$A$2:$A$957,0))),"",INDEX(Screener!$Q$2:$Q$957,MATCH($B31,Screener!$A$2:$A$957,0))),"") | N31: =IFERROR(IF(ISBLANK(INDEX(Screener!$AI$2:$AI$957,MATCH($B31,Screener!$A$2:$A$957,0))),"",INDEX(Screener!$AI$2:$AI$957,MATCH($B31,Screener!$A$2:$A$957,0))),"")
A32: 10 | B32: PTSP | C32: =IFERROR(IF(ISBLANK(INDEX(Screener!$B$2:$B$957,MATCH($B32,Screener!$A$2:$A$957,0))),"",INDEX(Screener!$B$2:$B$957,MATCH($B32,Screener!$A$2:$A$957,0))),"") | D32: =IFERROR(IF(ISBLANK(INDEX(Screener!$C$2:$C$957,MATCH($B32,Screener!$A$2:$A$957,0))),"",INDEX(Screener!$C$2:$C$957,MATCH($B32,Screener!$A$2:$A$957,0))),"") | E32: =IFERROR(IF(ISBLANK(INDEX(Screener!$D$2:$D$957,MATCH($B32,Screener!$A$2:$A$957,0))),"",INDEX(Screener!$D$2:$D$957,MATCH($B32,Screener!$A$2:$A$957,0))),"") | F32: =IFERROR(IF(ISBLANK(INDEX(Screener!$E$2:$E$957,MATCH($B32,Screener!$A$2:$A$957,0))),"",INDEX(Screener!$E$2:$E$957,MATCH($B32,Screener!$A$2:$A$957,0))),"") | G32: =IFERROR(IF(ISBLANK(INDEX(Screener!$AB$2:$AB$957,MATCH($B32,Screener!$A$2:$A$957,0))),"",INDEX(Screener!$AB$2:$AB$957,MATCH($B32,Screener!$A$2:$A$957,0))),"") | H32: =IFERROR(IF(ISBLANK(INDEX(Screener!$AC$2:$AC$957,MATCH($B32,Screener!$A$2:$A$957,0))),"",INDEX(Screener!$AC$2:$AC$957,MATCH($B32,Screener!$A$2:$A$957,0))),"") | I32: =IFERROR(IF(ISBLANK(INDEX(Screener!$AH$2:$AH$957,MATCH($B32,Screener!$A$2:$A$957,0))),"",INDEX(Screener!$AH$2:$AH$957,MATCH($B32,Screener!$A$2:$A$957,0))),"") | J32: =IFERROR(IF(ISBLANK(INDEX(Screener!$AE$2:$AE$957,MATCH($B32,Screener!$A$2:$A$957,0))),"",INDEX(Screener!$AE$2:$AE$957,MATCH($B32,Screener!$A$2:$A$957,0))),"") | K32: =IFERROR(IF(ISBLANK(INDEX(Screener!$AF$2:$AF$957,MATCH($B32,Screener!$A$2:$A$957,0))),"",INDEX(Screener!$AF$2:$AF$957,MATCH($B32,Screener!$A$2:$A$957,0))),"") | L32: =IFERROR(IF(ISBLANK(INDEX(Screener!$AG$2:$AG$957,MATCH($B32,Screener!$A$2:$A$957,0))),"",INDEX(Screener!$AG$2:$AG$957,MATCH($B32,Screener!$A$2:$A$957,0))),"") | M32: =IFERROR(IF(ISBLANK(INDEX(Screener!$Q$2:$Q$957,MATCH($B32,Screener!$A$2:$A$957,0))),"",INDEX(Screener!$Q$2:$Q$957,MATCH($B32,Screener!$A$2:$A$957,0))),"") | N32: =IFERROR(IF(ISBLANK(INDEX(Screener!$AI$2:$AI$957,MATCH($B32,Screener!$A$2:$A$957,0))),"",INDEX(Screener!$AI$2:$AI$957,MATCH($B32,Screener!$A$2:$A$957,0))),"")
A33: 11 | B33: DLTA | C33: =IFERROR(IF(ISBLANK(INDEX(Screener!$B$2:$B$957,MATCH($B33,Screener!$A$2:$A$957,0))),"",INDEX(Screener!$B$2:$B$957,MATCH($B33,Screener!$A$2:$A$957,0))),"") | D33: =IFERROR(IF(ISBLANK(INDEX(Screener!$C$2:$C$957,MATCH($B33,Screener!$A$2:$A$957,0))),"",INDEX(Screener!$C$2:$C$957,MATCH($B33,Screener!$A$2:$A$957,0))),"") | E33: =IFERROR(IF(ISBLANK(INDEX(Screener!$D$2:$D$957,MATCH($B33,Screener!$A$2:$A$957,0))),"",INDEX(Screener!$D$2:$D$957,MATCH($B33,Screener!$A$2:$A$957,0))),"") | F33: =IFERROR(IF(ISBLANK(INDEX(Screener!$E$2:$E$957,MATCH($B33,Screener!$A$2:$A$957,0))),"",INDEX(Screener!$E$2:$E$957,MATCH($B33,Screener!$A$2:$A$957,0))),"") | G33: =IFERROR(IF(ISBLANK(INDEX(Screener!$AB$2:$AB$957,MATCH($B33,Screener!$A$2:$A$957,0))),"",INDEX(Screener!$AB$2:$AB$957,MATCH($B33,Screener!$A$2:$A$957,0))),"") | H33: =IFERROR(IF(ISBLANK(INDEX(Screener!$AC$2:$AC$957,MATCH($B33,Screener!$A$2:$A$957,0))),"",INDEX(Screener!$AC$2:$AC$957,MATCH($B33,Screener!$A$2:$A$957,0))),"") | I33: =IFERROR(IF(ISBLANK(INDEX(Screener!$AH$2:$AH$957,MATCH($B33,Screener!$A$2:$A$957,0))),"",INDEX(Screener!$AH$2:$AH$957,MATCH($B33,Screener!$A$2:$A$957,0))),"") | J33: =IFERROR(IF(ISBLANK(INDEX(Screener!$AE$2:$AE$957,MATCH($B33,Screener!$A$2:$A$957,0))),"",INDEX(Screener!$AE$2:$AE$957,MATCH($B33,Screener!$A$2:$A$957,0))),"") | K33: =IFERROR(IF(ISBLANK(INDEX(Screener!$AF$2:$AF$957,MATCH($B33,Screener!$A$2:$A$957,0))),"",INDEX(Screener!$AF$2:$AF$957,MATCH($B33,Screener!$A$2:$A$957,0))),"") | L33: =IFERROR(IF(ISBLANK(INDEX(Screener!$AG$2:$AG$957,MATCH($B33,Screener!$A$2:$A$957,0))),"",INDEX(Screener!$AG$2:$AG$957,MATCH($B33,Screener!$A$2:$A$957,0))),"") | M33: =IFERROR(IF(ISBLANK(INDEX(Screener!$Q$2:$Q$957,MATCH($B33,Screener!$A$2:$A$957,0))),"",INDEX(Screener!$Q$2:$Q$957,MATCH($B33,Screener!$A$2:$A$957,0))),"") | N33: =IFERROR(IF(ISBLANK(INDEX(Screener!$AI$2:$AI$957,MATCH($B33,Screener!$A$2:$A$957,0))),"",INDEX(Screener!$AI$2:$AI$957,MATCH($B33,Screener!$A$2:$A$957,0))),"")
A34: 12 | B34: NISP | C34: =IFERROR(IF(ISBLANK(INDEX(Screener!$B$2:$B$957,MATCH($B34,Screener!$A$2:$A$957,0))),"",INDEX(Screener!$B$2:$B$957,MATCH($B34,Screener!$A$2:$A$957,0))),"") | D34: =IFERROR(IF(ISBLANK(INDEX(Screener!$C$2:$C$957,MATCH($B34,Screener!$A$2:$A$957,0))),"",INDEX(Screener!$C$2:$C$957,MATCH($B34,Screener!$A$2:$A$957,0))),"") | E34: =IFERROR(IF(ISBLANK(INDEX(Screener!$D$2:$D$957,MATCH($B34,Screener!$A$2:$A$957,0))),"",INDEX(Screener!$D$2:$D$957,MATCH($B34,Screener!$A$2:$A$957,0))),"") | F34: =IFERROR(IF(ISBLANK(INDEX(Screener!$E$2:$E$957,MATCH($B34,Screener!$A$2:$A$957,0))),"",INDEX(Screener!$E$2:$E$957,MATCH($B34,Screener!$A$2:$A$957,0))),"") | G34: =IFERROR(IF(ISBLANK(INDEX(Screener!$AB$2:$AB$957,MATCH($B34,Screener!$A$2:$A$957,0))),"",INDEX(Screener!$AB$2:$AB$957,MATCH($B34,Screener!$A$2:$A$957,0))),"") | H34: =IFERROR(IF(ISBLANK(INDEX(Screener!$AC$2:$AC$957,MATCH($B34,Screener!$A$2:$A$957,0))),"",INDEX(Screener!$AC$2:$AC$957,MATCH($B34,Screener!$A$2:$A$957,0))),"") | I34: =IFERROR(IF(ISBLANK(INDEX(Screener!$AH$2:$AH$957,MATCH($B34,Screener!$A$2:$A$957,0))),"",INDEX(Screener!$AH$2:$AH$957,MATCH($B34,Screener!$A$2:$A$957,0))),"") | J34: =IFERROR(IF(ISBLANK(INDEX(Screener!$AE$2:$AE$957,MATCH($B34,Screener!$A$2:$A$957,0))),"",INDEX(Screener!$AE$2:$AE$957,MATCH($B34,Screener!$A$2:$A$957,0))),"") | K34: =IFERROR(IF(ISBLANK(INDEX(Screener!$AF$2:$AF$957,MATCH($B34,Screener!$A$2:$A$957,0))),"",INDEX(Screener!$AF$2:$AF$957,MATCH($B34,Screener!$A$2:$A$957,0))),"") | L34: =IFERROR(IF(ISBLANK(INDEX(Screener!$AG$2:$AG$957,MATCH($B34,Screener!$A$2:$A$957,0))),"",INDEX(Screener!$AG$2:$AG$957,MATCH($B34,Screener!$A$2:$A$957,0))),"") | M34: =IFERROR(IF(ISBLANK(INDEX(Screener!$Q$2:$Q$957,MATCH($B34,Screener!$A$2:$A$957,0))),"",INDEX(Screener!$Q$2:$Q$957,MATCH($B34,Screener!$A$2:$A$957,0))),"") | N34: =IFERROR(IF(ISBLANK(INDEX(Screener!$AI$2:$AI$957,MATCH($B34,Screener!$A$2:$A$957,0))),"",INDEX(Screener!$AI$2:$AI$957,MATCH($B34,Screener!$A$2:$A$957,0))),"")
... A37: 15 | B37: ERAL | C37: =IFERROR(IF(ISBLANK(INDEX(Screener!$B$2:$B$957,MATCH($B37,Screener!$A$2:$A$957,0))),"",INDEX(Screener!$B$2:$B$957,MATCH($B37,Screener!$A$2:$A$957,0))),"") | D37: =IFERROR(IF(ISBLANK(INDEX(Screener!$C$2:$C$957,MATCH($B37,Screener!$A$2:$A$957,0))),"",INDEX(Screener!$C$2:$C$957,MATCH($B37,Screener!$A$2:$A$957,0))),"") | E37: =IFERROR(IF(ISBLANK(INDEX(Screener!$D$2:$D$957,MATCH($B37,Screener!$A$2:$A$957,0))),"",INDEX(Screener!$D$2:$D$957,MATCH($B37,Screener!$A$2:$A$957,0))),"") | F37: =IFERROR(IF(ISBLANK(INDEX(Screener!$E$2:$E$957,MATCH($B37,Screener!$A$2:$A$957,0))),"",INDEX(Screener!$E$2:$E$957,MATCH($B37,Screener!$A$2:$A$957,0))),"") | G37: =IFERROR(IF(ISBLANK(INDEX(Screener!$AB$2:$AB$957,MATCH($B37,Screener!$A$2:$A$957,0))),"",INDEX(Screener!$AB$2:$AB$957,MATCH($B37,Screener!$A$2:$A$957,0))),"") | H37: =IFERROR(IF(ISBLANK(INDEX(Screener!$AC$2:$AC$957,MATCH($B37,Screener!$A$2:$A$957,0))),"",INDEX(Screener!$AC$2:$AC$957,MATCH($B37,Screener!$A$2:$A$957,0))),"") | I37: =IFERROR(IF(ISBLANK(INDEX(Screener!$AH$2:$AH$957,MATCH($B37,Screener!$A$2:$A$957,0))),"",INDEX(Screener!$AH$2:$AH$957,MATCH($B37,Screener!$A$2:$A$957,0))),"") | J37: =IFERROR(IF(ISBLANK(INDEX(Screener!$AE$2:$AE$957,MATCH($B37,Screener!$A$2:$A$957,0))),"",INDEX(Screener!$AE$2:$AE$957,MATCH($B37,Screener!$A$2:$A$957,0))),"") | K37: =IFERROR(IF(ISBLANK(INDEX(Screener!$AF$2:$AF$957,MATCH($B37,Screener!$A$2:$A$957,0))),"",INDEX(Screener!$AF$2:$AF$957,MATCH($B37,Screener!$A$2:$A$957,0))),"") | L37: =IFERROR(IF(ISBLANK(INDEX(Screener!$AG$2:$AG$957,MATCH($B37,Screener!$A$2:$A$957,0))),"",INDEX(Screener!$AG$2:$AG$957,MATCH($B37,Screener!$A$2:$A$957,0))),"") | M37: =IFERROR(IF(ISBLANK(INDEX(Screener!$Q$2:$Q$957,MATCH($B37,Screener!$A$2:$A$957,0))),"",INDEX(Screener!$Q$2:$Q$957,MATCH($B37,Screener!$A$2:$A$957,0))),"") | N37: =IFERROR(IF(ISBLANK(INDEX(Screener!$AI$2:$AI$957,MATCH($B37,Screener!$A$2:$A$957,0))),"",INDEX(Screener!$AI$2:$AI$957,MATCH($B37,Screener!$A$2:$A$957,0))),"")
A39: CHEAPEST ON ACQUIRER'S MULTIPLE — lowest EV/EBIT, positive trailing EBIT only
A40: Rank | B40: Ticker | C40: Name | D40: Sector | E40: EV/EBIT | F40: Earnings Yield (EBIT/EV) | G40: ROC (Greenblatt) | H40: F-Score | I40: Altman Z | J40: Composite | K40: Verdict
A41: 1 | B41: CNKO | C41: =IFERROR(IF(ISBLANK(INDEX(Screener!$B$2:$B$957,MATCH($B41,Screener!$A$2:$A$957,0))),"",INDEX(Screener!$B$2:$B$957,MATCH($B41,Screener!$A$2:$A$957,0))),"") | D41: =IFERROR(IF(ISBLANK(INDEX(Screener!$C$2:$C$957,MATCH($B41,Screener!$A$2:$A$957,0))),"",INDEX(Screener!$C$2:$C$957,MATCH($B41,Screener!$A$2:$A$957,0))),"") | E41: =IFERROR(IF(ISBLANK(INDEX(Screener!$I$2:$I$957,MATCH($B41,Screener!$A$2:$A$957,0))),"",INDEX(Screener!$I$2:$I$957,MATCH($B41,Screener!$A$2:$A$957,0))),"") | F41: =IFERROR(IF(ISBLANK(INDEX(Screener!$O$2:$O$957,MATCH($B41,Screener!$A$2:$A$957,0))),"",INDEX(Screener!$O$2:$O$957,MATCH($B41,Screener!$A$2:$A$957,0))),"") | G41: =IFERROR(IF(ISBLANK(INDEX(Screener!$N$2:$N$957,MATCH($B41,Screener!$A$2:$A$957,0))),"",INDEX(Screener!$N$2:$N$957,MATCH($B41,Screener!$A$2:$A$957,0))),"") | H41: =IFERROR(IF(ISBLANK(INDEX(Screener!$Q$2:$Q$957,MATCH($B41,Screener!$A$2:$A$957,0))),"",INDEX(Screener!$Q$2:$Q$957,MATCH($B41,Screener!$A$2:$A$957,0))),"") | I41: =IFERROR(IF(ISBLANK(INDEX(Screener!$R$2:$R$957,MATCH($B41,Screener!$A$2:$A$957,0))),"",INDEX(Screener!$R$2:$R$957,MATCH($B41,Screener!$A$2:$A$957,0))),"") | J41: =IFERROR(IF(ISBLANK(INDEX(Screener!$AH$2:$AH$957,MATCH($B41,Screener!$A$2:$A$957,0))),"",INDEX(Screener!$AH$2:$AH$957,MATCH($B41,Screener!$A$2:$A$957,0))),"") | K41: =IFERROR(IF(ISBLANK(INDEX(Screener!$AI$2:$AI$957,MATCH($B41,Screener!$A$2:$A$957,0))),"",INDEX(Screener!$AI$2:$AI$957,MATCH($B41,Screener!$A$2:$A$957,0))),"")
A42: 2 | B42: LSIP | C42: =IFERROR(IF(ISBLANK(INDEX(Screener!$B$2:$B$957,MATCH($B42,Screener!$A$2:$A$957,0))),"",INDEX(Screener!$B$2:$B$957,MATCH($B42,Screener!$A$2:$A$957,0))),"") | D42: =IFERROR(IF(ISBLANK(INDEX(Screener!$C$2:$C$957,MATCH($B42,Screener!$A$2:$A$957,0))),"",INDEX(Screener!$C$2:$C$957,MATCH($B42,Screener!$A$2:$A$957,0))),"") | E42: =IFERROR(IF(ISBLANK(INDEX(Screener!$I$2:$I$957,MATCH($B42,Screener!$A$2:$A$957,0))),"",INDEX(Screener!$I$2:$I$957,MATCH($B42,Screener!$A$2:$A$957,0))),"") | F42: =IFERROR(IF(ISBLANK(INDEX(Screener!$O$2:$O$957,MATCH($B42,Screener!$A$2:$A$957,0))),"",INDEX(Screener!$O$2:$O$957,MATCH($B42,Screener!$A$2:$A$957,0))),"") | G42: =IFERROR(IF(ISBLANK(INDEX(Screener!$N$2:$N$957,MATCH($B42,Screener!$A$2:$A$957,0))),"",INDEX(Screener!$N$2:$N$957,MATCH($B42,Screener!$A$2:$A$957,0))),"") | H42: =IFERROR(IF(ISBLANK(INDEX(Screener!$Q$2:$Q$957,MATCH($B42,Screener!$A$2:$A$957,0))),"",INDEX(Screener!$Q$2:$Q$957,MATCH($B42,Screener!$A$2:$A$957,0))),"") | I42: =IFERROR(IF(ISBLANK(INDEX(Screener!$R$2:$R$957,MATCH($B42,Screener!$A$2:$A$957,0))),"",INDEX(Screener!$R$2:$R$957,MATCH($B42,Screener!$A$2:$A$957,0))),"") | J42: =IFERROR(IF(ISBLANK(INDEX(Screener!$AH$2:$AH$957,MATCH($B42,Screener!$A$2:$A$957,0))),"",INDEX(Screener!$AH$2:$AH$957,MATCH($B42,Screener!$A$2:$A$957,0))),"") | K42: =IFERROR(IF(ISBLANK(INDEX(Screener!$AI$2:$AI$957,MATCH($B42,Screener!$A$2:$A$957,0))),"",INDEX(Screener!$AI$2:$AI$957,MATCH($B42,Screener!$A$2:$A$957,0))),"")
A43: 3 | B43: RIGS | C43: =IFERROR(IF(ISBLANK(INDEX(Screener!$B$2:$B$957,MATCH($B43,Screener!$A$2:$A$957,0))),"",INDEX(Screener!$B$2:$B$957,MATCH($B43,Screener!$A$2:$A$957,0))),"") | D43: =IFERROR(IF(ISBLANK(INDEX(Screener!$C$2:$C$957,MATCH($B43,Screener!$A$2:$A$957,0))),"",INDEX(Screener!$C$2:$C$957,MATCH($B43,Screener!$A$2:$A$957,0))),"") | E43: =IFERROR(IF(ISBLANK(INDEX(Screener!$I$2:$I$957,MATCH($B43,Screener!$A$2:$A$957,0))),"",INDEX(Screener!$I$2:$I$957,MATCH($B43,Screener!$A$2:$A$957,0))),"") | F43: =IFERROR(IF(ISBLANK(INDEX(Screener!$O$2:$O$957,MATCH($B43,Screener!$A$2:$A$957,0))),"",INDEX(Screener!$O$2:$O$957,MATCH($B43,Screener!$A$2:$A$957,0))),"") | G43: =IFERROR(IF(ISBLANK(INDEX(Screener!$N$2:$N$957,MATCH($B43,Screener!$A$2:$A$957,0))),"",INDEX(Screener!$N$2:$N$957,MATCH($B43,Screener!$A$2:$A$957,0))),"") | H43: =IFERROR(IF(ISBLANK(INDEX(Screener!$Q$2:$Q$957,MATCH($B43,Screener!$A$2:$A$957,0))),"",INDEX(Screener!$Q$2:$Q$957,MATCH($B43,Screener!$A$2:$A$957,0))),"") | I43: =IFERROR(IF(ISBLANK(INDEX(Screener!$R$2:$R$957,MATCH($B43,Screener!$A$2:$A$957,0))),"",INDEX(Screener!$R$2:$R$957,MATCH($B43,Screener!$A$2:$A$957,0))),"") | J43: =IFERROR(IF(ISBLANK(INDEX(Screener!$AH$2:$AH$957,MATCH($B43,Screener!$A$2:$A$957,0))),"",INDEX(Screener!$AH$2:$AH$957,MATCH($B43,Screener!$A$2:$A$957,0))),"") | K43: =IFERROR(IF(ISBLANK(INDEX(Screener!$AI$2:$AI$957,MATCH($B43,Screener!$A$2:$A$957,0))),"",INDEX(Screener!$AI$2:$AI$957,MATCH($B43,Screener!$A$2:$A$957,0))),"")
A44: 4 | B44: SRTG | C44: =IFERROR(IF(ISBLANK(INDEX(Screener!$B$2:$B$957,MATCH($B44,Screener!$A$2:$A$957,0))),"",INDEX(Screener!$B$2:$B$957,MATCH($B44,Screener!$A$2:$A$957,0))),"") | D44: =IFERROR(IF(ISBLANK(INDEX(Screener!$C$2:$C$957,MATCH($B44,Screener!$A$2:$A$957,0))),"",INDEX(Screener!$C$2:$C$957,MATCH($B44,Screener!$A$2:$A$957,0))),"") | E44: =IFERROR(IF(ISBLANK(INDEX(Screener!$I$2:$I$957,MATCH($B44,Screener!$A$2:$A$957,0))),"",INDEX(Screener!$I$2:$I$957,MATCH($B44,Screener!$A$2:$A$957,0))),"") | F44: =IFERROR(IF(ISBLANK(INDEX(Screener!$O$2:$O$957,MATCH($B44,Screener!$A$2:$A$957,0))),"",INDEX(Screener!$O$2:$O$957,MATCH($B44,Screener!$A$2:$A$957,0))),"") | G44: =IFERROR(IF(ISBLANK(INDEX(Screener!$N$2:$N$957,MATCH($B44,Screener!$A$2:$A$957,0))),"",INDEX(Screener!$N$2:$N$957,MATCH($B44,Screener!$A$2:$A$957,0))),"") | H44: =IFERROR(IF(ISBLANK(INDEX(Screener!$Q$2:$Q$957,MATCH($B44,Screener!$A$2:$A$957,0))),"",INDEX(Screener!$Q$2:$Q$957,MATCH($B44,Screener!$A$2:$A$957,0))),"") | I44: =IFERROR(IF(ISBLANK(INDEX(Screener!$R$2:$R$957,MATCH($B44,Screener!$A$2:$A$957,0))),"",INDEX(Screener!$R$2:$R$957,MATCH($B44,Screener!$A$2:$A$957,0))),"") | J44: =IFERROR(IF(ISBLANK(INDEX(Screener!$AH$2:$AH$957,MATCH($B44,Screener!$A$2:$A$957,0))),"",INDEX(Screener!$AH$2:$AH$957,MATCH($B44,Screener!$A$2:$A$957,0))),"") | K44: =IFERROR(IF(ISBLANK(INDEX(Screener!$AI$2:$AI$957,MATCH($B44,Screener!$A$2:$A$957,0))),"",INDEX(Screener!$AI$2:$AI$957,MATCH($B44,Screener!$A$2:$A$957,0))),"")
A45: 5 | B45: TPIA | C45: =IFERROR(IF(ISBLANK(INDEX(Screener!$B$2:$B$957,MATCH($B45,Screener!$A$2:$A$957,0))),"",INDEX(Screener!$B$2:$B$957,MATCH($B45,Screener!$A$2:$A$957,0))),"") | D45: =IFERROR(IF(ISBLANK(INDEX(Screener!$C$2:$C$957,MATCH($B45,Screener!$A$2:$A$957,0))),"",INDEX(Screener!$C$2:$C$957,MATCH($B45,Screener!$A$2:$A$957,0))),"") | E45: =IFERROR(IF(ISBLANK(INDEX(Screener!$I$2:$I$957,MATCH($B45,Screener!$A$2:$A$957,0))),"",INDEX(Screener!$I$2:$I$957,MATCH($B45,Screener!$A$2:$A$957,0))),"") | F45: =IFERROR(IF(ISBLANK(INDEX(Screener!$O$2:$O$957,MATCH($B45,Screener!$A$2:$A$957,0))),"",INDEX(Screener!$O$2:$O$957,MATCH($B45,Screener!$A$2:$A$957,0))),"") | G45: =IFERROR(IF(ISBLANK(INDEX(Screener!$N$2:$N$957,MATCH($B45,Screener!$A$2:$A$957,0))),"",INDEX(Screener!$N$2:$N$957,MATCH($B45,Screener!$A$2:$A$957,0))),"") | H45: =IFERROR(IF(ISBLANK(INDEX(Screener!$Q$2:$Q$957,MATCH($B45,Screener!$A$2:$A$957,0))),"",INDEX(Screener!$Q$2:$Q$957,MATCH($B45,Screener!$A$2:$A$957,0))),"") | I45: =IFERROR(IF(ISBLANK(INDEX(Screener!$R$2:$R$957,MATCH($B45,Screener!$A$2:$A$957,0))),"",INDEX(Screener!$R$2:$R$957,MATCH($B45,Screener!$A$2:$A$957,0))),"") | J45: =IFERROR(IF(ISBLANK(INDEX(Screener!$AH$2:$AH$957,MATCH($B45,Screener!$A$2:$A$957,0))),"",INDEX(Screener!$AH$2:$AH$957,MATCH($B45,Screener!$A$2:$A$957,0))),"") | K45: =IFERROR(IF(ISBLANK(INDEX(Screener!$AI$2:$AI$957,MATCH($B45,Screener!$A$2:$A$957,0))),"",INDEX(Screener!$AI$2:$AI$957,MATCH($B45,Screener!$A$2:$A$957,0))),"")
A46: 6 | B46: IGAR | C46: =IFERROR(IF(ISBLANK(INDEX(Screener!$B$2:$B$957,MATCH($B46,Screener!$A$2:$A$957,0))),"",INDEX(Screener!$B$2:$B$957,MATCH($B46,Screener!$A$2:$A$957,0))),"") | D46: =IFERROR(IF(ISBLANK(INDEX(Screener!$C$2:$C$957,MATCH($B46,Screener!$A$2:$A$957,0))),"",INDEX(Screener!$C$2:$C$957,MATCH($B46,Screener!$A$2:$A$957,0))),"") | E46: =IFERROR(IF(ISBLANK(INDEX(Screener!$I$2:$I$957,MATCH($B46,Screener!$A$2:$A$957,0))),"",INDEX(Screener!$I$2:$I$957,MATCH($B46,Screener!$A$2:$A$957,0))),"") | F46: =IFERROR(IF(ISBLANK(INDEX(Screener!$O$2:$O$957,MATCH($B46,Screener!$A$2:$A$957,0))),"",INDEX(Screener!$O$2:$O$957,MATCH($B46,Screener!$A$2:$A$957,0))),"") | G46: =IFERROR(IF(ISBLANK(INDEX(Screener!$N$2:$N$957,MATCH($B46,Screener!$A$2:$A$957,0))),"",INDEX(Screener!$N$2:$N$957,MATCH($B46,Screener!$A$2:$A$957,0))),"") | H46: =IFERROR(IF(ISBLANK(INDEX(Screener!$Q$2:$Q$957,MATCH($B46,Screener!$A$2:$A$957,0))),"",INDEX(Screener!$Q$2:$Q$957,MATCH($B46,Screener!$A$2:$A$957,0))),"") | I46: =IFERROR(IF(ISBLANK(INDEX(Screener!$R$2:$R$957,MATCH($B46,Screener!$A$2:$A$957,0))),"",INDEX(Screener!$R$2:$R$957,MATCH($B46,Screener!$A$2:$A$957,0))),"") | J46: =IFERROR(IF(ISBLANK(INDEX(Screener!$AH$2:$AH$957,MATCH($B46,Screener!$A$2:$A$957,0))),"",INDEX(Screener!$AH$2:$AH$957,MATCH($B46,Screener!$A$2:$A$957,0))),"") | K46: =IFERROR(IF(ISBLANK(INDEX(Screener!$AI$2:$AI$957,MATCH($B46,Screener!$A$2:$A$957,0))),"",INDEX(Screener!$AI$2:$AI$957,MATCH($B46,Screener!$A$2:$A$957,0))),"")
A47: 7 | B47: SCCO | C47: =IFERROR(IF(ISBLANK(INDEX(Screener!$B$2:$B$957,MATCH($B47,Screener!$A$2:$A$957,0))),"",INDEX(Screener!$B$2:$B$957,MATCH($B47,Screener!$A$2:$A$957,0))),"") | D47: =IFERROR(IF(ISBLANK(INDEX(Screener!$C$2:$C$957,MATCH($B47,Screener!$A$2:$A$957,0))),"",INDEX(Screener!$C$2:$C$957,MATCH($B47,Screener!$A$2:$A$957,0))),"") | E47: =IFERROR(IF(ISBLANK(INDEX(Screener!$I$2:$I$957,MATCH($B47,Screener!$A$2:$A$957,0))),"",INDEX(Screener!$I$2:$I$957,MATCH($B47,Screener!$A$2:$A$957,0))),"") | F47: =IFERROR(IF(ISBLANK(INDEX(Screener!$O$2:$O$957,MATCH($B47,Screener!$A$2:$A$957,0))),"",INDEX(Screener!$O$2:$O$957,MATCH($B47,Screener!$A$2:$A$957,0))),"") | G47: =IFERROR(IF(ISBLANK(INDEX(Screener!$N$2:$N$957,MATCH($B47,Screener!$A$2:$A$957,0))),"",INDEX(Screener!$N$2:$N$957,MATCH($B47,Screener!$A$2:$A$957,0))),"") | H47: =IFERROR(IF(ISBLANK(INDEX(Screener!$Q$2:$Q$957,MATCH($B47,Screener!$A$2:$A$957,0))),"",INDEX(Screener!$Q$2:$Q$957,MATCH($B47,Screener!$A$2:$A$957,0))),"") | I47: =IFERROR(IF(ISBLANK(INDEX(Screener!$R$2:$R$957,MATCH($B47,Screener!$A$2:$A$957,0))),"",INDEX(Screener!$R$2:$R$957,MATCH($B47,Screener!$A$2:$A$957,0))),"") | J47: =IFERROR(IF(ISBLANK(INDEX(Screener!$AH$2:$AH$957,MATCH($B47,Screener!$A$2:$A$957,0))),"",INDEX(Screener!$AH$2:$AH$957,MATCH($B47,Screener!$A$2:$A$957,0))),"") | K47: =IFERROR(IF(ISBLANK(INDEX(Screener!$AI$2:$AI$957,MATCH($B47,Screener!$A$2:$A$957,0))),"",INDEX(Screener!$AI$2:$AI$957,MATCH($B47,Screener!$A$2:$A$957,0))),"")
...

Sheet Screener
A1: Ticker | B1: Name | C1: Sector | D1: Business Type | E1: Price | F1: Market Cap (IDR bn) | G1: PE (TTM) | H1: PB | I1: EV/EBIT | J1: EV/EBITDA | K1: Div Yield | L1: ROE | M1: ROIC | N1: ROC (Greenblatt) | O1: Earnings Yield (EBIT/EV) | P1: FCF Yield | Q1: F-Score | R1: Altman Z | S1: Current Ratio | T1: Net Debt/Equity | U1: Rev CAGR 3Y | V1: NCAV/share | W1: Net-Net Pass | X1: EPV/share | Y1: IV Bear | Z1: IV Base | AA1: IV Bull | AB1: Blended IV | AC1: MOS | AD1: Upside | AE1: Quality | AF1: Safety | AG1: Value | AH1: Composite | AI1: Verdict | AJ1: Quarters Stale | AK1: Red Flags | AL1: _row in RAW_key_statistics | AM1: _row in RAW_scores | AN1: _row in RAW_idx_stocks | AO1: _row in RAW_analyses
A2: AADI | B2: =IFERROR(IF(ISBLANK(INDEX(RAW_scores!$B$2:$B$957,$AM2)),"",INDEX(RAW_scores!$B$2:$B$957,$AM2)),"") | C2: =IFERROR(IF(ISBLANK(INDEX(RAW_scores!$C$2:$C$957,$AM2)),"",INDEX(RAW_scores!$C$2:$C$957,$AM2)),"") | D2: =IFERROR(IF(ISBLANK(INDEX(RAW_scores!$D$2:$D$957,$AM2)),"",INDEX(RAW_scores!$D$2:$D$957,$AM2)),"") | E2: =IFERROR(IF(ISBLANK(INDEX(RAW_idx_stocks!$F$2:$F$957,$AN2)),"",INDEX(RAW_idx_stocks!$F$2:$F$957,$AN2)),"") | F2: =IFERROR(IF(ISBLANK(INDEX(RAW_key_statistics!$BS$2:$BS$957,$AL2)),"",INDEX(RAW_key_statistics!$BS$2:$BS$957,$AL2)/1000000000),"") | G2: =IFERROR(IF(ISBLANK(INDEX(RAW_key_statistics!$C$2:$C$957,$AL2)),"",INDEX(RAW_key_statistics!$C$2:$C$957,$AL2)),"") | H2: =IFERROR(IF(ISBLANK(INDEX(RAW_key_statistics!$H$2:$H$957,$AL2)),"",INDEX(RAW_key_statistics!$H$2:$H$957,$AL2)),"") | I2: =IFERROR(IF(ISBLANK(INDEX(RAW_key_statistics!$K$2:$K$957,$AL2)),"",INDEX(RAW_key_statistics!$K$2:$K$957,$AL2)),"") | J2: =IFERROR(IF(ISBLANK(INDEX(RAW_key_statistics!$L$2:$L$957,$AL2)),"",INDEX(RAW_key_statistics!$L$2:$L$957,$AL2)),"") | K2: =IFERROR(IF(ISBLANK(INDEX(RAW_key_statistics!$AZ$2:$AZ$957,$AL2)),"",INDEX(RAW_key_statistics!$AZ$2:$AZ$957,$AL2)),"") | L2: =IFERROR(IF(ISBLANK(INDEX(RAW_key_statistics!$AG$2:$AG$957,$AL2)),"",INDEX(RAW_key_statistics!$AG$2:$AG$957,$AL2)),"") | M2: =IFERROR(IF(ISBLANK(INDEX(RAW_key_statistics!$AI$2:$AI$957,$AL2)),"",INDEX(RAW_key_statistics!$AI$2:$AI$957,$AL2)),"") | N2: =IFERROR(IF(ISBLANK(INDEX(RAW_key_statistics!$CI$2:$CI$957,$AL2)),"",INDEX(RAW_key_statistics!$CI$2:$CI$957,$AL2)),"") | O2: =IFERROR(IF(ISBLANK(INDEX(RAW_key_statistics!$CH$2:$CH$957,$AL2)),"",INDEX(RAW_key_statistics!$CH$2:$CH$957,$AL2)),"") | P2: =IFERROR(IF(ISBLANK(INDEX(RAW_key_statistics!$CK$2:$CK$957,$AL2)),"",INDEX(RAW_key_statistics!$CK$2:$CK$957,$AL2)),"") | Q2: =IFERROR(IF(ISBLANK(INDEX(RAW_key_statistics!$BB$2:$BB$957,$AL2)),"",INDEX(RAW_key_statistics!$BB$2:$BB$957,$AL2)),"") | R2: =IFERROR(IF(ISBLANK(INDEX(RAW_key_statistics!$AE$2:$AE$957,$AL2)),"",INDEX(RAW_key_statistics!$AE$2:$AE$957,$AL2)),"") | S2: =IFERROR(IF(ISBLANK(INDEX(RAW_key_statistics!$V$2:$V$957,$AL2)),"",INDEX(RAW_key_statistics!$V$2:$V$957,$AL2)),"") | T2: =IFERROR(IF(ISBLANK(INDEX(RAW_analyses!$N$2:$N$957,$AO2)),"",INDEX(RAW_analyses!$N$2:$N$957,$AO2)),"") | U2: =IFERROR(IF(ISBLANK(INDEX(RAW_key_statistics!$CU$2:$CU$957,$AL2)),"",INDEX(RAW_key_statistics!$CU$2:$CU$957,$AL2)),"") | V2: =IFERROR(IF(ISBLANK(INDEX(RAW_key_statistics!$CM$2:$CM$957,$AL2)),"",INDEX(RAW_key_statistics!$CM$2:$CM$957,$AL2)),"") | W2: =IFERROR(IF(ISBLANK(INDEX(RAW_key_statistics!$CN$2:$CN$957,$AL2)),"",INDEX(RAW_key_statistics!$CN$2:$CN$957,$AL2)),"") | X2: =IFERROR(IF(ISBLANK(INDEX(RAW_key_statistics!$CR$2:$CR$957,$AL2)),"",INDEX(RAW_key_statistics!$CR$2:$CR$957,$AL2)),"") | Y2: =IFERROR(IF(ISBLANK(INDEX(RAW_scores!$R$2:$R$957,$AM2)),"",INDEX(RAW_scores!$R$2:$R$957,$AM2)),"") | Z2: =IFERROR(IF(ISBLANK(INDEX(RAW_scores!$S$2:$S$957,$AM2)),"",INDEX(RAW_scores!$S$2:$S$957,$AM2)),"") | AA2: =IFERROR(IF(ISBLANK(INDEX(RAW_scores!$T$2:$T$957,$AM2)),"",INDEX(RAW_scores!$T$2:$T$957,$AM2)),"") | AB2: =IFERROR(IF(ISBLANK(INDEX(RAW_scores!$X$2:$X$957,$AM2)),"",INDEX(RAW_scores!$X$2:$X$957,$AM2)),"") | AC2: =IFERROR(IF(ISBLANK(INDEX(RAW_scores!$Y$2:$Y$957,$AM2)),"",INDEX(RAW_scores!$Y$2:$Y$957,$AM2)),"") | AD2: =IFERROR(IF(ISBLANK(INDEX(RAW_scores!$Z$2:$Z$957,$AM2)),"",INDEX(RAW_scores!$Z$2:$Z$957,$AM2)),"") | AE2: =IFERROR(IF(ISBLANK(INDEX(RAW_scores!$F$2:$F$957,$AM2)),"",INDEX(RAW_scores!$F$2:$F$957,$AM2)),"") | AF2: =IFERROR(IF(ISBLANK(INDEX(RAW_scores!$G$2:$G$957,$AM2)),"",INDEX(RAW_scores!$G$2:$G$957,$AM2)),"") | AG2: =IFERROR(IF(ISBLANK(INDEX(RAW_scores!$H$2:$H$957,$AM2)),"",INDEX(RAW_scores!$H$2:$H$957,$AM2)),"") | AH2: =IFERROR(IF(ISBLANK(INDEX(RAW_scores!$I$2:$I$957,$AM2)),"",INDEX(RAW_scores!$I$2:$I$957,$AM2)),"") | AI2: =IFERROR(IF(ISBLANK(INDEX(RAW_scores!$AA$2:$AA$957,$AM2)),"",INDEX(RAW_scores!$AA$2:$AA$957,$AM2)),"") | AJ2: =IFERROR(IF(ISBLANK(INDEX(RAW_scores!$AF$2:$AF$957,$AM2)),"",INDEX(RAW_scores!$AF$2:$AF$957,$AM2)),"") | AK2: =IFERROR(IF(ISBLANK(INDEX(RAW_scores!$AC$2:$AC$957,$AM2)),"",INDEX(RAW_scores!$AC$2:$AC$957,$AM2)),"") | AL2: =IFERROR(MATCH($A2,RAW_key_statistics!$A$2:$A$957,0),"") | AM2: =IFERROR(MATCH($A2,RAW_scores!$A$2:$A$957,0),"") | AN2: =IFERROR(MATCH($A2,RAW_idx_stocks!$A$2:$A$957,0),"") | AO2: =IFERROR(MATCH($A2,RAW_analyses!$A$2:$A$957,0),"")
A3: AALI | B3: =IFERROR(IF(ISBLANK(INDEX(RAW_scores!$B$2:$B$957,$AM3)),"",INDEX(RAW_scores!$B$2:$B$957,$AM3)),"") | C3: =IFERROR(IF(ISBLANK(INDEX(RAW_scores!$C$2:$C$957,$AM3)),"",INDEX(RAW_scores!$C$2:$C$957,$AM3)),"") | D3: =IFERROR(IF(ISBLANK(INDEX(RAW_scores!$D$2:$D$957,$AM3)),"",INDEX(RAW_scores!$D$2:$D$957,$AM3)),"") | E3: =IFERROR(IF(ISBLANK(INDEX(RAW_idx_stocks!$F$2:$F$957,$AN3)),"",INDEX(RAW_idx_stocks!$F$2:$F$957,$AN3)),"") | F3: =IFERROR(IF(ISBLANK(INDEX(RAW_key_statistics!$BS$2:$BS$957,$AL3)),"",INDEX(RAW_key_statistics!$BS$2:$BS$957,$AL3)/1000000000),"") | G3: =IFERROR(IF(ISBLANK(INDEX(RAW_key_statistics!$C$2:$C$957,$AL3)),"",INDEX(RAW_key_statistics!$C$2:$C$957,$AL3)),"") | H3: =IFERROR(IF(ISBLANK(INDEX(RAW_key_statistics!$H$2:$H$957,$AL3)),"",INDEX(RAW_key_statistics!$H$2:$H$957,$AL3)),"") | I3: =IFERROR(IF(ISBLANK(INDEX(RAW_key_statistics!$K$2:$K$957,$AL3)),"",INDEX(RAW_key_statistics!$K$2:$K$957,$AL3)),"") | J3: =IFERROR(IF(ISBLANK(INDEX(RAW_key_statistics!$L$2:$L$957,$AL3)),"",INDEX(RAW_key_statistics!$L$2:$L$957,$AL3)),"") | K3: =IFERROR(IF(ISBLANK(INDEX(RAW_key_statistics!$AZ$2:$AZ$957,$AL3)),"",INDEX(RAW_key_statistics!$AZ$2:$AZ$957,$AL3)),"") | L3: =IFERROR(IF(ISBLANK(INDEX(RAW_key_statistics!$AG$2:$AG$957,$AL3)),"",INDEX(RAW_key_statistics!$AG$2:$AG$957,$AL3)),"") | M3: =IFERROR(IF(ISBLANK(INDEX(RAW_key_statistics!$AI$2:$AI$957,$AL3)),"",INDEX(RAW_key_statistics!$AI$2:$AI$957,$AL3)),"") | N3: =IFERROR(IF(ISBLANK(INDEX(RAW_key_statistics!$CI$2:$CI$957,$AL3)),"",INDEX(RAW_key_statistics!$CI$2:$CI$957,$AL3)),"") | O3: =IFERROR(IF(ISBLANK(INDEX(RAW_key_statistics!$CH$2:$CH$957,$AL3)),"",INDEX(RAW_key_statistics!$CH$2:$CH$957,$AL3)),"") | P3: =IFERROR(IF(ISBLANK(INDEX(RAW_key_statistics!$CK$2:$CK$957,$AL3)),"",INDEX(RAW_key_statistics!$CK$2:$CK$957,$AL3)),"") | Q3: =IFERROR(IF(ISBLANK(INDEX(RAW_key_statistics!$BB$2:$BB$957,$AL3)),"",INDEX(RAW_key_statistics!$BB$2:$BB$957,$AL3)),"") | R3: =IFERROR(IF(ISBLANK(INDEX(RAW_key_statistics!$AE$2:$AE$957,$AL3)),"",INDEX(RAW_key_statistics!$AE$2:$AE$957,$AL3)),"") | S3: =IFERROR(IF(ISBLANK(INDEX(RAW_key_statistics!$V$2:$V$957,$AL3)),"",INDEX(RAW_key_statistics!$V$2:$V$957,$AL3)),"") | T3: =IFERROR(IF(ISBLANK(INDEX(RAW_analyses!$N$2:$N$957,$AO3)),"",INDEX(RAW_analyses!$N$2:$N$957,$AO3)),"") | U3: =IFERROR(IF(ISBLANK(INDEX(RAW_key_statistics!$CU$2:$CU$957,$AL3)),"",INDEX(RAW_key_statistics!$CU$2:$CU$957,$AL3)),"") | V3: =IFERROR(IF(ISBLANK(INDEX(RAW_key_statistics!$CM$2:$CM$957,$AL3)),"",INDEX(RAW_key_statistics!$CM$2:$CM$957,$AL3)),"") | W3: =IFERROR(IF(ISBLANK(INDEX(RAW_key_statistics!$CN$2:$CN$957,$AL3)),"",INDEX(RAW_key_statistics!$CN$2:$CN$957,$AL3)),"") | X3: =IFERROR(IF(ISBLANK(INDEX(RAW_key_statistics!$CR$2:$CR$957,$AL3)),"",INDEX(RAW_key_statistics!$CR$2:$CR$957,$AL3)),"") | Y3: =IFERROR(IF(ISBLANK(INDEX(RAW_scores!$R$2:$R$957,$AM3)),"",INDEX(RAW_scores!$R$2:$R$957,$AM3)),"") | Z3: =IFERROR(IF(ISBLANK(INDEX(RAW_scores!$S$2:$S$957,$AM3)),"",INDEX(RAW_scores!$S$2:$S$957,$AM3)),"") | AA3: =IFERROR(IF(ISBLANK(INDEX(RAW_scores!$T$2:$T$957,$AM3)),"",INDEX(RAW_scores!$T$2:$T$957,$AM3)),"") | AB3: =IFERROR(IF(ISBLANK(INDEX(RAW_scores!$X$2:$X$957,$AM3)),"",INDEX(RAW_scores!$X$2:$X$957,$AM3)),"") | AC3: =IFERROR(IF(ISBLANK(INDEX(RAW_scores!$Y$2:$Y$957,$AM3)),"",INDEX(RAW_scores!$Y$2:$Y$957,$AM3)),"") | AD3: =IFERROR(IF(ISBLANK(INDEX(RAW_scores!$Z$2:$Z$957,$AM3)),"",INDEX(RAW_scores!$Z$2:$Z$957,$AM3)),"") | AE3: =IFERROR(IF(ISBLANK(INDEX(RAW_scores!$F$2:$F$957,$AM3)),"",INDEX(RAW_scores!$F$2:$F$957,$AM3)),"") | AF3: =IFERROR(IF(ISBLANK(INDEX(RAW_scores!$G$2:$G$957,$AM3)),"",INDEX(RAW_scores!$G$2:$G$957,$AM3)),"") | AG3: =IFERROR(IF(ISBLANK(INDEX(RAW_scores!$H$2:$H$957,$AM3)),"",INDEX(RAW_scores!$H$2:$H$957,$AM3)),"") | AH3: =IFERROR(IF(ISBLANK(INDEX(RAW_scores!$I$2:$I$957,$AM3)),"",INDEX(RAW_scores!$I$2:$I$957,$AM3)),"") | AI3: =IFERROR(IF(ISBLANK(INDEX(RAW_scores!$AA$2:$AA$957,$AM3)),"",INDEX(RAW_scores!$AA$2:$AA$957,$AM3)),"") | AJ3: =IFERROR(IF(ISBLANK(INDEX(RAW_scores!$AF$2:$AF$957,$AM3)),"",INDEX(RAW_scores!$AF$2:$AF$957,$AM3)),"") | AK3: =IFERROR(IF(ISBLANK(INDEX(RAW_scores!$AC$2:$AC$957,$AM3)),"",INDEX(RAW_scores!$AC$2:$AC$957,$AM3)),"") | AL3: =IFERROR(MATCH($A3,RAW_key_statistics!$A$2:$A$957,0),"") | AM3: =IFERROR(MATCH($A3,RAW_scores!$A$2:$A$957,0),"") | AN3: =IFERROR(MATCH($A3,RAW_idx_stocks!$A$2:$A$957,0),"") | AO3: =IFERROR(MATCH($A3,RAW_analyses!$A$2:$A$957,0),"")
A4: ABBA | B4: =IFERROR(IF(ISBLANK(INDEX(RAW_scores!$B$2:$B$957,$AM4)),"",INDEX(RAW_scores!$B$2:$B$957,$AM4)),"") | C4: =IFERROR(IF(ISBLANK(INDEX(RAW_scores!$C$2:$C$957,$AM4)),"",INDEX(RAW_scores!$C$2:$C$957,$AM4)),"") | D4: =IFERROR(IF(ISBLANK(INDEX(RAW_scores!$D$2:$D$957,$AM4)),"",INDEX(RAW_scores!$D$2:$D$957,$AM4)),"") | E4: =IFERROR(IF(ISBLANK(INDEX(RAW_idx_stocks!$F$2:$F$957,$AN4)),"",INDEX(RAW_idx_stocks!$F$2:$F$957,$AN4)),"") | F4: =IFERROR(IF(ISBLANK(INDEX(RAW_key_statistics!$BS$2:$BS$957,$AL4)),"",INDEX(RAW_key_statistics!$BS$2:$BS$957,$AL4)/1000000000),"") | G4: =IFERROR(IF(ISBLANK(INDEX(RAW_key_statistics!$C$2:$C$957,$AL4)),"",INDEX(RAW_key_statistics!$C$2:$C$957,$AL4)),"") | H4: =IFERROR(IF(ISBLANK(INDEX(RAW_key_statistics!$H$2:$H$957,$AL4)),"",INDEX(RAW_key_statistics!$H$2:$H$957,$AL4)),"") | I4: =IFERROR(IF(ISBLANK(INDEX(RAW_key_statistics!$K$2:$K$957,$AL4)),"",INDEX(RAW_key_statistics!$K$2:$K$957,$AL4)),"") | J4: =IFERROR(IF(ISBLANK(INDEX(RAW_key_statistics!$L$2:$L$957,$AL4)),"",INDEX(RAW_key_statistics!$L$2:$L$957,$AL4)),"") | K4: =IFERROR(IF(ISBLANK(INDEX(RAW_key_statistics!$AZ$2:$AZ$957,$AL4)),"",INDEX(RAW_key_statistics!$AZ$2:$AZ$957,$AL4)),"") | L4: =IFERROR(IF(ISBLANK(INDEX(RAW_key_statistics!$AG$2:$AG$957,$AL4)),"",INDEX(RAW_key_statistics!$AG$2:$AG$957,$AL4)),"") | M4: =IFERROR(IF(ISBLANK(INDEX(RAW_key_statistics!$AI$2:$AI$957,$AL4)),"",INDEX(RAW_key_statistics!$AI$2:$AI$957,$AL4)),"") | N4: =IFERROR(IF(ISBLANK(INDEX(RAW_key_statistics!$CI$2:$CI$957,$AL4)),"",INDEX(RAW_key_statistics!$CI$2:$CI$957,$AL4)),"") | O4: =IFERROR(IF(ISBLANK(INDEX(RAW_key_statistics!$CH$2:$CH$957,$AL4)),"",INDEX(RAW_key_statistics!$CH$2:$CH$957,$AL4)),"") | P4: =IFERROR(IF(ISBLANK(INDEX(RAW_key_statistics!$CK$2:$CK$957,$AL4)),"",INDEX(RAW_key_statistics!$CK$2:$CK$957,$AL4)),"") | Q4: =IFERROR(IF(ISBLANK(INDEX(RAW_key_statistics!$BB$2:$BB$957,$AL4)),"",INDEX(RAW_key_statistics!$BB$2:$BB$957,$AL4)),"") | R4: =IFERROR(IF(ISBLANK(INDEX(RAW_key_statistics!$AE$2:$AE$957,$AL4)),"",INDEX(RAW_key_statistics!$AE$2:$AE$957,$AL4)),"") | S4: =IFERROR(IF(ISBLANK(INDEX(RAW_key_statistics!$V$2:$V$957,$AL4)),"",INDEX(RAW_key_statistics!$V$2:$V$957,$AL4)),"") | T4: =IFERROR(IF(ISBLANK(INDEX(RAW_analyses!$N$2:$N$957,$AO4)),"",INDEX(RAW_analyses!$N$2:$N$957,$AO4)),"") | U4: =IFERROR(IF(ISBLANK(INDEX(RAW_key_statistics!$CU$2:$CU$957,$AL4)),"",INDEX(RAW_key_statistics!$CU$2:$CU$957,$AL4)),"") | V4: =IFERROR(IF(ISBLANK(INDEX(RAW_key_statistics!$CM$2:$CM$957,$AL4)),"",INDEX(RAW_key_statistics!$CM$2:$CM$957,$AL4)),"") | W4: =IFERROR(IF(ISBLANK(INDEX(RAW_key_statistics!$CN$2:$CN$957,$AL4)),"",INDEX(RAW_key_statistics!$CN$2:$CN$957,$AL4)),"") | X4: =IFERROR(IF(ISBLANK(INDEX(RAW_key_statistics!$CR$2:$CR$957,$AL4)),"",INDEX(RAW_key_statistics!$CR$2:$CR$957,$AL4)),"") | Y4: =IFERROR(IF(ISBLANK(INDEX(RAW_scores!$R$2:$R$957,$AM4)),"",INDEX(RAW_scores!$R$2:$R$957,$AM4)),"") | Z4: =IFERROR(IF(ISBLANK(INDEX(RAW_scores!$S$2:$S$957,$AM4)),"",INDEX(RAW_scores!$S$2:$S$957,$AM4)),"") | AA4: =IFERROR(IF(ISBLANK(INDEX(RAW_scores!$T$2:$T$957,$AM4)),"",INDEX(RAW_scores!$T$2:$T$957,$AM4)),"") | AB4: =IFERROR(IF(ISBLANK(INDEX(RAW_scores!$X$2:$X$957,$AM4)),"",INDEX(RAW_scores!$X$2:$X$957,$AM4)),"") | AC4: =IFERROR(IF(ISBLANK(INDEX(RAW_scores!$Y$2:$Y$957,$AM4)),"",INDEX(RAW_scores!$Y$2:$Y$957,$AM4)),"") | AD4: =IFERROR(IF(ISBLANK(INDEX(RAW_scores!$Z$2:$Z$957,$AM4)),"",INDEX(RAW_scores!$Z$2:$Z$957,$AM4)),"") | AE4: =IFERROR(IF(ISBLANK(INDEX(RAW_scores!$F$2:$F$957,$AM4)),"",INDEX(RAW_scores!$F$2:$F$957,$AM4)),"") | AF4: =IFERROR(IF(ISBLANK(INDEX(RAW_scores!$G$2:$G$957,$AM4)),"",INDEX(RAW_scores!$G$2:$G$957,$AM4)),"") | AG4: =IFERROR(IF(ISBLANK(INDEX(RAW_scores!$H$2:$H$957,$AM4)),"",INDEX(RAW_scores!$H$2:$H$957,$AM4)),"") | AH4: =IFERROR(IF(ISBLANK(INDEX(RAW_scores!$I$2:$I$957,$AM4)),"",INDEX(RAW_scores!$I$2:$I$957,$AM4)),"") | AI4: =IFERROR(IF(ISBLANK(INDEX(RAW_scores!$AA$2:$AA$957,$AM4)),"",INDEX(RAW_scores!$AA$2:$AA$957,$AM4)),"") | AJ4: =IFERROR(IF(ISBLANK(INDEX(RAW_scores!$AF$2:$AF$957,$AM4)),"",INDEX(RAW_scores!$AF$2:$AF$957,$AM4)),"") | AK4: =IFERROR(IF(ISBLANK(INDEX(RAW_scores!$AC$2:$AC$957,$AM4)),"",INDEX(RAW_scores!$AC$2:$AC$957,$AM4)),"") | AL4: =IFERROR(MATCH($A4,RAW_key_statistics!$A$2:$A$957,0),"") | AM4: =IFERROR(MATCH($A4,RAW_scores!$A$2:$A$957,0),"") | AN4: =IFERROR(MATCH($A4,RAW_idx_stocks!$A$2:$A$957,0),"") | AO4: =IFERROR(MATCH($A4,RAW_analyses!$A$2:$A$957,0),"")
A5: ABDA | B5: =IFERROR(IF(ISBLANK(INDEX(RAW_scores!$B$2:$B$957,$AM5)),"",INDEX(RAW_scores!$B$2:$B$957,$AM5)),"") | C5: =IFERROR(IF(ISBLANK(INDEX(RAW_scores!$C$2:$C$957,$AM5)),"",INDEX(RAW_scores!$C$2:$C$957,$AM5)),"") | D5: =IFERROR(IF(ISBLANK(INDEX(RAW_scores!$D$2:$D$957,$AM5)),"",INDEX(RAW_scores!$D$2:$D$957,$AM5)),"") | E5: =IFERROR(IF(ISBLANK(INDEX(RAW_idx_stocks!$F$2:$F$957,$AN5)),"",INDEX(RAW_idx_stocks!$F$2:$F$957,$AN5)),"") | F5: =IFERROR(IF(ISBLANK(INDEX(RAW_key_statistics!$BS$2:$BS$957,$AL5)),"",INDEX(RAW_key_statistics!$BS$2:$BS$957,$AL5)/1000000000),"") | G5: =IFERROR(IF(ISBLANK(INDEX(RAW_key_statistics!$C$2:$C$957,$AL5)),"",INDEX(RAW_key_statistics!$C$2:$C$957,$AL5)),"") | H5: =IFERROR(IF(ISBLANK(INDEX(RAW_key_statistics!$H$2:$H$957,$AL5)),"",INDEX(RAW_key_statistics!$H$2:$H$957,$AL5)),"") | I5: =IFERROR(IF(ISBLANK(INDEX(RAW_key_statistics!$K$2:$K$957,$AL5)),"",INDEX(RAW_key_statistics!$K$2:$K$957,$AL5)),"") | J5: =IFERROR(IF(ISBLANK(INDEX(RAW_key_statistics!$L$2:$L$957,$AL5)),"",INDEX(RAW_key_statistics!$L$2:$L$957,$AL5)),"") | K5: =IFERROR(IF(ISBLANK(INDEX(RAW_key_statistics!$AZ$2:$AZ$957,$AL5)),"",INDEX(RAW_key_statistics!$AZ$2:$AZ$957,$AL5)),"") | L5: =IFERROR(IF(ISBLANK(INDEX(RAW_key_statistics!$AG$2:$AG$957,$AL5)),"",INDEX(RAW_key_statistics!$AG$2:$AG$957,$AL5)),"") | M5: =IFERROR(IF(ISBLANK(INDEX(RAW_key_statistics!$AI$2:$AI$957,$AL5)),"",INDEX(RAW_key_statistics!$AI$2:$AI$957,$AL5)),"") | N5: =IFERROR(IF(ISBLANK(INDEX(RAW_key_statistics!$CI$2:$CI$957,$AL5)),"",INDEX(RAW_key_statistics!$CI$2:$CI$957,$AL5)),"") | O5: =IFERROR(IF(ISBLANK(INDEX(RAW_key_statistics!$CH$2:$CH$957,$AL5)),"",INDEX(RAW_key_statistics!$CH$2:$CH$957,$AL5)),"") | P5: =IFERROR(IF(ISBLANK(INDEX(RAW_key_statistics!$CK$2:$CK$957,$AL5)),"",INDEX(RAW_key_statistics!$CK$2:$CK$957,$AL5)),"") | Q5: =IFERROR(IF(ISBLANK(INDEX(RAW_key_statistics!$BB$2:$BB$957,$AL5)),"",INDEX(RAW_key_statistics!$BB$2:$BB$957,$AL5)),"") | R5: =IFERROR(IF(ISBLANK(INDEX(RAW_key_statistics!$AE$2:$AE$957,$AL5)),"",INDEX(RAW_key_statistics!$AE$2:$AE$957,$AL5)),"") | S5: =IFERROR(IF(ISBLANK(INDEX(RAW_key_statistics!$V$2:$V$957,$AL5)),"",INDEX(RAW_key_statistics!$V$2:$V$957,$AL5)),"") | T5: =IFERROR(IF(ISBLANK(INDEX(RAW_analyses!$N$2:$N$957,$AO5)),"",INDEX(RAW_analyses!$N$2:$N$957,$AO5)),"") | U5: =IFERROR(IF(ISBLANK(INDEX(RAW_key_statistics!$CU$2:$CU$957,$AL5)),"",INDEX(RAW_key_statistics!$CU$2:$CU$957,$AL5)),"") | V5: =IFERROR(IF(ISBLANK(INDEX(RAW_key_statistics!$CM$2:$CM$957,$AL5)),"",INDEX(RAW_key_statistics!$CM$2:$CM$957,$AL5)),"") | W5: =IFERROR(IF(ISBLANK(INDEX(RAW_key_statistics!$CN$2:$CN$957,$AL5)),"",INDEX(RAW_key_statistics!$CN$2:$CN$957,$AL5)),"") | X5: =IFERROR(IF(ISBLANK(INDEX(RAW_key_statistics!$CR$2:$CR$957,$AL5)),"",INDEX(RAW_key_statistics!$CR$2:$CR$957,$AL5)),"") | Y5: =IFERROR(IF(ISBLANK(INDEX(RAW_scores!$R$2:$R$957,$AM5)),"",INDEX(RAW_scores!$R$2:$R$957,$AM5)),"") | Z5: =IFERROR(IF(ISBLANK(INDEX(RAW_scores!$S$2:$S$957,$AM5)),"",INDEX(RAW_scores!$S$2:$S$957,$AM5)),"") | AA5: =IFERROR(IF(ISBLANK(INDEX(RAW_scores!$T$2:$T$957,$AM5)),"",INDEX(RAW_scores!$T$2:$T$957,$AM5)),"") | AB5: =IFERROR(IF(ISBLANK(INDEX(RAW_scores!$X$2:$X$957,$AM5)),"",INDEX(RAW_scores!$X$2:$X$957,$AM5)),"") | AC5: =IFERROR(IF(ISBLANK(INDEX(RAW_scores!$Y$2:$Y$957,$AM5)),"",INDEX(RAW_scores!$Y$2:$Y$957,$AM5)),"") | AD5: =IFERROR(IF(ISBLANK(INDEX(RAW_scores!$Z$2:$Z$957,$AM5)),"",INDEX(RAW_scores!$Z$2:$Z$957,$AM5)),"") | AE5: =IFERROR(IF(ISBLANK(INDEX(RAW_scores!$F$2:$F$957,$AM5)),"",INDEX(RAW_scores!$F$2:$F$957,$AM5)),"") | AF5: =IFERROR(IF(ISBLANK(INDEX(RAW_scores!$G$2:$G$957,$AM5)),"",INDEX(RAW_scores!$G$2:$G$957,$AM5)),"") | AG5: =IFERROR(IF(ISBLANK(INDEX(RAW_scores!$H$2:$H$957,$AM5)),"",INDEX(RAW_scores!$H$2:$H$957,$AM5)),"") | AH5: =IFERROR(IF(ISBLANK(INDEX(RAW_scores!$I$2:$I$957,$AM5)),"",INDEX(RAW_scores!$I$2:$I$957,$AM5)),"") | AI5: =IFERROR(IF(ISBLANK(INDEX(RAW_scores!$AA$2:$AA$957,$AM5)),"",INDEX(RAW_scores!$AA$2:$AA$957,$AM5)),"") | AJ5: =IFERROR(IF(ISBLANK(INDEX(RAW_scores!$AF$2:$AF$957,$AM5)),"",INDEX(RAW_scores!$AF$2:$AF$957,$AM5)),"") | AK5: =IFERROR(IF(ISBLANK(INDEX(RAW_scores!$AC$2:$AC$957,$AM5)),"",INDEX(RAW_scores!$AC$2:$AC$957,$AM5)),"") | AL5: =IFERROR(MATCH($A5,RAW_key_statistics!$A$2:$A$957,0),"") | AM5: =IFERROR(MATCH($A5,RAW_scores!$A$2:$A$957,0),"") | AN5: =IFERROR(MATCH($A5,RAW_idx_stocks!$A$2:$A$957,0),"") | AO5: =IFERROR(MATCH($A5,RAW_analyses!$A$2:$A$957,0),"")
